Workbook

Sheet نموذج (3)
A1: الاسم | B1: تاريخ الميلاد | C1: الرقم القومي | D1: رقم الجواز | E1: المنفذ | F1: جهة السفر | G1: شركة الطيران | H1: تاريخ المغادرة | I1: ميعاد المغادرة | J1: الوكيل | K1: مورد الاستثمار | L1: ملاحظات | M1: نوع الخدمه | N1: ملاحظات | O1: ملاحظات | P1: ملاحظات | Q1: مدين دولار | R1: دائن دولار | S1: مدين مصري | T1: دائن مصري
EM110: =EM110 -> 0

Sheet نموذج (2)
A1: الاسم | B1: تاريخ الميلاد | C1: الرقم القومي | D1: رقم الجواز | E1: المنفذ | F1: جهة السفر | G1: شركة الطيران | H1: تاريخ المغادرة | I1: ميعاد المغادرة | J1: الوكيل | K1: مورد الاستثمار | L1: ملاحظات | M1: نوع الخدمه | N1: ملاحظات | O1: ملاحظات | P1: ملاحظات | Q1: مدين دولار | R1: دائن دولار | S1: مدين مصري | T1: دائن مصري
AL359: 22200
HL697: =#REF! -> #REF!
HH1016: =HH1016 -> 0

Sheet الرئيسيه
B1: اجمالى حسابات العمالة المصرية طيران و بري
A2: م | B2: اسم الوكيل | C2: اجمالي المديونيه $ | D2: اجمالي المديونيه EGP
A3: 1 | B3: المليجي | C3: =المليجي!J720 -> 0 | D3: =المليجي!J721 -> 10894 | E3: =D3/45200 -> 0.2410177
A4: 2 | B4: ضياء الجملي | C4: ='ضياء الجملي'!J851 -> 0 | D4: ='ضياء الجملي'!J852 -> -775650 | E4: =D4/45200 -> -17.160398
A5: 3 | B5: حمدي الجازوي | C5: ='حمدي الجازوي'!J1366 -> 0 | D5: ='حمدي الجازوي'!J1367 -> -315953 | E5: =D5/45200 -> -6.9901106
A6: 4 | B6: صابر | C6: =SUM(منصور!H794) -> 0 | D6: =SUM(صابر!J549) -> -1171900 | E6: =D6/45200 -> -25.926991
A7: 5 | B7: هاي لايت | C7: =SUM('شركه هاي لايتس'!J20) -> 0 | D7: =SUM('شركه هاي لايتس'!J21) -> 0 | E7: =D7/45200 -> 0
A8: 6 | B8: لاكي | C8: =SUM(لاكي!J11) -> 1700 | D8: =SUM('شركه هاي لايتس'!J21) -> 0 | E8: =D8/45200 -> 0
A9: 7 | B9: ابو رحمة | C9: ='أبو رحمه'!J276 -> 0 | D9: ='أبو رحمه'!J277 -> -154901 | E9: =D9/45200 -> -3.4270133
A10: 8 | B10: ابو عطيه | C10: ='أبو عطيه'!J1231 -> 0 | D10: ='أبو عطيه'!J1232 -> 451271 | E10: =D10/45200 -> 9.9838717
A11: 9 | B11: م رضا | C11: ='م رضا '!J590 -> 0 | D11: ='م رضا '!J591 -> 53906 | E11: =D11/45200 -> 1.1926106
A12: 10 | B12: عبد الرحمن زاهر | C12: ='عبدالرحمن زاهر'!J657 -> 0 | D12: ='عبدالرحمن زاهر'!J658 -> -261950 | E12: =D12/45200 -> -5.795354
A13: 11 | B13: تامر عفيفي | C13: ='تامر عفيفي'!J166 -> 0 | D13: ='تامر عفيفي'!J167 -> 159721.5 | E13: =D13/45200 -> 3.5336615
A14: 12 | B14: الحاج كارم | C14: ='الحاج كارم'!J336 -> 0 | D14: ='الحاج كارم'!J337 -> -38433 | E14: =D14/45200 -> -0.85028761
A15: 13 | B15: محمد عبد الله (المميز) | C15: ='محمد عبدالله'!J357 -> 0 | D15: ='محمد عبدالله'!J358 -> -336810 | E15: =D15/45200 -> -7.4515487
A16: 14 | B16: سعفان رافع | C16: ='سعفان رافع'!J683 -> -740 | D16: ='سعفان رافع'!J684 -> 232878 | E16: =D16/45200 -> 5.1521681
A17: 15 | B17: عبد الرحمن الليبية | C17: ='عبدالرحمن الليبيه'!J300 -> 0 | D17: ='عبدالرحمن الليبيه'!J301 -> -166754 | E17: =D17/45200 -> -3.6892478
A18: 16 | B18: جادو | C18: =جادو!J223 -> -800 | D18: =جادو!J224 -> -29458 | E18: =D18/45200 -> -0.65172566
A19: 17 | B19: خالد الزعيم | C19: ='خالد الزعيم'!J233 -> 0 | D19: ='خالد الزعيم'!J234 -> -7917 | E19: =D19/45200 -> -0.17515487
A20: 18 | B20: الحاج بدر | C20: ='الحاج بدر'!J249 -> -375 | D20: ='الحاج بدر'!J250 -> -105453 | E20: =D20/45200 -> -2.333031
A21: 19 | B21: ناجي العربي | C21: ='ناجي العربي'!J881 -> 0 | D21: ='ناجي العربي'!J882 -> -207580 | E21: =D21/45200 -> -4.5924779
A22: 20 | B22: عادل نصار | C22: ='عادل نصار'!J83 -> -750 | D22: ='عادل نصار'!J84 -> -37 | E22: =D22/45200 -> -0.00081858407
A23: 21 | B23: الحاج مجدي | C23: =SUM('الحاج مجدي'!J115) -> 0 | D23: =SUM('الحاج مجدي'!J116) -> -8875 | E23: =D23/45200 -> -0.19634956
A24: 22 | B24: الزاجل | C24: =الزاجل!J11 -> 0 | D24: =الزاجل!J12 -> -86300 | E24: =D24/45200 -> -1.909292
A25: 23 | B25: محمد صبحي | C25: ='فلاي ليبيا'!J113 -> 0 | D25: ='فلاي ليبيا'!J114 -> 0 | E25: =D25/45200 -> 0
A26: 24 | B26: السويسي | C26: =السويسي!J506 -> 0 | D26: =السويسي!J507 -> 561125 | E26: =D26/45200 -> 12.41427
A27: 25 | B27: ايزي ترافيل | C27: ='ايزي ترافيل'!J38 -> 113825 | D27: ='ايزي ترافيل'!J39 -> -249232 | E27: =D27/45200 -> -5.5139823
A28: 26 | B28: شركة العنوان (اعمار ليبيا) | C28: =العنوان!J19 -> 0 | D28: =العنوان!J20 -> -41985 | E28: =D28/45200 -> -0.92887168
A29: 27 | B29: البشاير | C29: =البشائر!J72 -> 0 | D29: =البشائر!J73 -> -37899 | E29: =D29/45200 -> -0.83847345
A30: 28 | B30: وائل العبدلي | C30: ='وائل العبدلي'!J43 -> 125 | D30: ='وائل العبدلي'!J44 -> 86850 | E30: =D30/45200 -> 1.9214602
A31: 29 | B31: ريهام | C31: =ريهام!J53 -> 0 | D31: =ريهام!J54 -> 24000 | E31: =D31/45200 -> 0.53097345
A32: 30 | B32: تايجر | C32: =SUM(تايجر!J39) -> 0 | D32: =SUM(تايجر!J38,تايجر!J40) -> 0 | E32: =D32/45200 -> 0
A33: 31 | B33: الحاجه عفاف | C33: =عفاف!J277 -> 0 | D33: =عفاف!J278 -> -49552 | E33: =D33/45200 -> -1.0962832
A34: 32 | B34: ايمن حامد | C34: ='ايمن حامد'!J62 -> 0 | D34: ='ايمن حامد'!J63 -> -200 | E34: =D34/45200 -> -0.0044247788
A35: 33 | B35: كابلات مصر | C35: ='كابلات مصر'!J11 -> 0 | D35: ='كابلات مصر'!J12 -> -21000 | E35: =D35/45200 -> -0.46460177
A36: 34 | B36: مزار مصر | C36: ='مزار مصر'!J393 -> 0 | D36: ='مزار مصر'!J394 -> 56551 | E36: =D36/45200 -> 1.2511283
A37: 35 | B37: عبدالحليم رشوان | C37: =SUM('عبد الحليم رشوان'!J11) -> 0 | D37: =SUM('عبد الحليم رشوان'!J12) -> 0 | E37: =D37/45200 -> 0
A38: 36 | B38: الصياد | C38: =الصياد!J21 -> 625 | D38: =الصياد!J22 -> -3675 | E38: =D38/45200 -> -0.08130531
A39: 37 | B39: غيث يامن | C39: ='غيث يامن'!J61 -> 0 | D39: ='غيث يامن'!J62 -> 166 | E39: =D39/45200 -> 0.0036725664
A40: 38 | B40: حسام حلمي | C40: ='حسام حلمي'!J11 -> 0 | D40: ='حسام حلمي'!J12 -> 0 | E40: =D40/45200 -> 0
...

Sheet حساب التحالف
C2: حساب/ مسحوبات وايداعات التحالف
B4: التاريخ | C4: المسحوبات | D4: المدفوعات | E4: الرصيد
B5: 46334 | E5: 22800730
B6: 46364 | D6: 1500000 | E6: =E5+C6-D6 -> 21300730
B7: 46364 | C7: 7876660 | E7: =E6+C7-D7 -> 29177390
B8: 13/8/2026 | C8: 5664675 | E8: =E7+C8-D8 -> 34842065
B9: 14/8/2026 | C9: 2616065 | E9: =E8+C9-D9 -> 37458130
B10: 15/8/2026 | D10: 10000000 | E10: =E9+C10-D10 -> 27458130
B11: 15/8/2026 | D11: 2000000 | E11: =E10+C11-D11 -> 25458130
B12: 15/8/2026 | D12: 1500000 | E12: =E11+C12-D12 -> 23958130
B13: 15/8/2026 | D13: 3548250 | E13: =E12+C13-D13 -> 20409880
B14: 15/8/2026 | C14: 5174585 | E14: =E13+C14-D14 -> 25584465
B15: 16/8/2026 | C15: 8581075 | E15: =E14+C15-D15 -> 34165540
B16: 17/8/2026 | D16: 1000000 | E16: =E15+C16-D16 -> 33165540
B17: 17/8/2026 | D17: 2580000 | E17: =E16+C17-D17 -> 30585540
B18: 17/8/2026 | C18: 6484680 | E18: =E17+C18-D18 -> 37070220
B19: 18/8/2026 | C19: 4012535 | E19: =E18+C19-D19 -> 41082755
B20: 19/8/2026 | D20: 3642300 | E20: =E19+C20-D20 -> 37440455
B21: 19/8/2026 | D21: 3000000 | E21: =E20+C21-D21 -> 34440455
B22: 19/8/2026 | D22: 10000000 | E22: =E21+C22-D22 -> 24440455
B23: 19/8/2026 | D23: 1000000 | E23: =E22+C23-D23 -> 23440455
B24: 19/8/2026 | C24: 5191110 | E24: =E23+C24-D24 -> 28631565
B25: 20/8/2026 | D25: 2000000 | E25: =E24+C25-D25 -> 26631565
B26: 20/8/2026 | D26: 1500000 | E26: =E25+C26-D26 -> 25131565
B27: 20/8/2026 | D27: 20000000 | E27: =E26+C27-D27 -> 5131565
B28: 20/8/2026 | C28: 6049875 | E28: =E27+C28-D28 -> 11181440
B29: 21/8/2026 | C29: 6784895 | E29: =E28+C29-D29 -> 17966335
B30: 22/8/2026 | C30: 2666700 | E30: =E29+C30-D30 -> 20633035
B31: 23/8/2026 | D31: 5000000 | E31: =E30+C31-D31 -> 15633035
B32: 23/8/2026 | D32: 1000000 | E32: =E31+C32-D32 -> 14633035
B33: 23/8/2026 | D33: 1900000 | E33: =E32+C33-D33 -> 12733035
B34: 23/8/2026 | C34: 5248000 | E34: =E33+C34-D34 -> 17981035
B35: 24/8/2026 | D35: 2000000 | E35: =E34+C35-D35 -> 15981035
B36: 24/8/2026 | C36: 5179000 | E36: =E35+C36-D36 -> 21160035
B37: 25/8/2026 | D37: 1328900 | E37: =E36+C37-D37 -> 19831135
B38: 25/8/2026 | D38: 2000000 | E38: =E37+C38-D38 -> 17831135
B39: 25/8/2026 | C39: 8212000 | E39: =E38+C39-D39 -> 26043135
B40: 26/8/2026 | D40: 6000000 | E40: =E39+C40-D40 -> 20043135
B41: 26/8/2026 | D41: 1500000 | E41: =E40+C41-D41 -> 18543135
B42: 26/8/2026 | D42: 4000000 | E42: =E41+C42-D42 -> 14543135
...

Sheet خزنه احمد سامح
D2: حساب / الخزنه
C4: التاريخ | D4: البيان | E4: مدين | F4: دائن | G4: الرصيد | H4: التاريخ | I4: البيان | J4: مدين $ | K4: دائن $ | L4: رصيد
C5: 25/6/2026 | D5: رصيد اول المده | G5: 11400505 | H5: 25/6/2026 | L5: 48900
C6: 25/6/2026 | D6: طيران البراق طرابلس | F6: 796470 | G6: =G5+E6-F6 -> 10604035 | H6: 28/6/2026 | I6: نيو ايدج | J6: 3000 | L6: =L5+J6-K6 -> 51900
C7: 25/6/2026 | D7: طيران البراق طرابلس | F7: 128190 | G7: =G6+E7-F7 -> 10475845 | L7: =L6+J7-K7 -> 51900
C8: 27/6/2026 | D8: منصور | E8: 619000 | G8: =G7+E8-F8 -> 11094845 | H8: 28/6/2026 | I8: غيث | J8: 800 | L8: =L7+J8-K8 -> 52700
C9: 27/6/2026 | D9: فاطمه الجازوي | E9: 300000 | G9: =G8+E9-F9 -> 11394845 | H9: 28/6/2026 | I9: تامر عفيفي | J9: 4000 | L9: =L8+J9-K9 -> 56700
C10: 27/6/2026 | D10: ناجي العربي | E10: 1185000 | G10: =G9+E10-F10 -> 12579845 | H10: 29/6/2026 | I10: غيث | J10: 1000 | L10: =L9+J10-K10 -> 57700
C11: 27/6/2026 | D11: ابو عطيه | E11: 1303650 | G11: =G10+E11-F11 -> 13883495 | H11: 29/6/2026 | I11: مزار مصر | J11: 250 | L11: =L10+J11-K11 -> 57950
C12: 27/6/2026 | D12: مزار مصر | E12: 1114000 | G12: =G11+E12-F12 -> 14997495 | H12: 30/6/2026 | I12: اللواء حاتم محمود | J12: 350 | L12: =L11+J12-K12 -> 58300
C13: 27/6/2026 | D13: حمدي الجازوي | E13: 1089500 | G13: =G12+E13-F13 -> 16086995 | H13: 46060 | I13: رد من ح ايزي ترافل | K13: 1400 | L13: =L12+J13-K13 -> 56900
C14: 28/6/2026 | D14: هاليبرتون محمد ثروت | E14: 22000 | G14: =G13+E14-F14 -> 16108995 | H14: 46119 | I14: عبد العزيز سعفان | J14: 900 | L14: =L13+J14-K14 -> 57800
C15: 28/6/2026 | D15: رد من حساب م عزه | F15: 18000 | G15: =G14+E15-F15 -> 16090995 | H15: 46119 | I15: توريد جنسيات | K15: 5000 | L15: =L14+J15-K15 -> 52800
C16: 28/6/2026 | D16: محمد عبد الله | E16: 620000 | G16: =G15+E16-F16 -> 16710995 | H16: 46149 | I16: غيث | J16: 3000 | L16: =L15+J16-K16 -> 55800
C17: 28/6/2026 | D17: ابو رحمه | E17: 550000 | G17: =G16+E17-F17 -> 17260995 | H17: 46149 | I17: خروج للحج رافع | K17: 2400 | L17: =L16+J17-K17 -> 53400
C18: 28/6/2026 | D18: محمد عبد الله | E18: 100000 | G18: =G17+E18-F18 -> 17360995 | H18: 46180 | I18: نيو ايدج | J18: 1000 | L18: =L17+J18-K18 -> 54400
C19: 28/6/2026 | D19: توريد دروب | F19: 10000000 | G19: =G18+E19-F19 -> 7360995 | H19: 46210 | I19: المليجي | J19: 6500 | L19: =L18+J19-K19 -> 60900
C20: 28/6/2026 | D20: غيث | E20: 27000 | G20: =G19+E20-F20 -> 7387995 | H20: 46241 | I20: خروج للتحالف | K20: 10000 | L20: =L19+J20-K20 -> 50900
C21: 28/6/2026 | D21: ام سالم | E21: 210000 | G21: =G20+E21-F21 -> 7597995 | H21: 46241 | I21: تامر عفيفي | J21: 4700 | L21: =L20+J21-K21 -> 55600
C22: 29/6/2026 | D22: محمد عبد الله | E22: 350000 | G22: =G21+E22-F22 -> 7947995 | H22: 46241 | I22: غيث | J22: 500 | L22: =L21+J22-K22 -> 56100
C23: 29/6/2026 | D23: ام سالم | E23: 50000 | G23: =G22+E23-F23 -> 7997995 | H23: 46363 | I23: فاطمه | J23: 1000 | L23: =L22+J23-K23 -> 57100
C24: 29/6/2026 | D24: محمد عبد الله | E24: 100000 | G24: =G23+E24-F24 -> 8097995 | H24: 13/7/2026 | I24: الحاج بدر | J24: 350 | L24: =L23+J24-K24 -> 57450
C25: 29/6/2026 | D25: تامر عفيفي | E25: 250000 | G25: =G24+E25-F25 -> 8347995 | H25: 14/7/2026 | I25: خروج لميرا | K25: 4900 | L25: =L24+J25-K25 -> 52550
C26: 29/6/2026 | D26: اكرم المنقوش | E26: 12000 | G26: =G25+E26-F26 -> 8359995 | H26: 14/7/2026 | I26: نيو ايدج | J26: 3600 | L26: =L25+J26-K26 -> 56150
C27: 29/6/2026 | D27: م رضا | E27: 499400 | G27: =G26+E27-F27 -> 8859395 | H27: 14/7/2026 | I27: تامر عفيفي | J27: 1100 | L27: =L26+J27-K27 -> 57250
C28: 29/6/2026 | D28: السويسي | E28: 580000 | G28: =G27+E28-F28 -> 9439395 | H28: 16/7/2026 | I28: خروج لايزي ترافل | K28: 3000 | L28: =L27+J28-K28 -> 54250
C29: 29/6/2026 | D29: م رضا | E29: 167000 | G29: =G28+E29-F29 -> 9606395 | H29: 19/7/2026 | I29: عفاف | J29: 6200 | L29: =L28+J29-K29 -> 60450
C30: 29/6/2026 | D30: خالد نجيب | E30: 815000 | G30: =G29+E30-F30 -> 10421395 | H30: 20/7/2026 | I30: مزار مصر | J30: 600 | L30: =L29+J30-K30 -> 61050
C31: 29/6/2026 | D31: فلاي ليبيا | E31: 492000 | G31: =G30+E31-F31 -> 10913395 | H31: 20/7/2026 | I31: علي عمر | J31: 8000 | L31: =L30+J31-K31 -> 69050
C32: 29/6/2026 | D32: مزار مصر | E32: 1258650 | G32: =G31+E32-F32 -> 12172045 | H32: 20/7/2026 | I32: الحاج بدر | J32: 850 | L32: =L31+J32-K32 -> 69900
C33: 30/6/2026 | D33: تايجر | E33: 308000 | G33: =G32+E33-F33 -> 12480045 | H33: 24/7/2026 | I33: تامر عفيفي | J33: 4000 | L33: =L32+J33-K33 -> 73900
C34: 30/6/2026 | D34: احمد مجدي | E34: 100000 | G34: =G33+E34-F34 -> 12580045 | H34: 28/7/2026 | I34: البهلول | J34: 3000 | L34: =L33+J34-K34 -> 76900
C35: 30/6/2026 | D35: ريحاليستا | E35: 600000 | G35: =G34+E35-F35 -> 13180045 | H35: 28/7/2026 | I35: البهلول | J35: 400 | L35: =L34+J35-K35 -> 77300
C36: 30/6/2026 | D36: ام سالم | E36: 120000 | G36: =G35+E36-F36 -> 13300045 | H36: 30/7/2026 | I36: عادل نصار | J36: 2000 | L36: =L35+J36-K36 -> 79300
C37: 30/6/2026 | D37: السويسي | E37: 730000 | G37: =G36+E37-F37 -> 14030045 | H37: 31/7/2026 | I37: غيث | J37: 1000 | L37: =L36+J37-K37 -> 80300
C38: 30/6/2026 | D38: حمدي الجازوي | E38: 930000 | G38: =G37+E38-F38 -> 14960045 | H38: 46030 | I38: جنسيات | K38: 5000 | L38: =L37+J38-K38 -> 75300
C39: 30/6/2026 | D39: م رضا | E39: 300000 | G39: =G38+E39-F39 -> 15260045 | H39: 46030 | I39: تامر عفيفي | J39: 4985 | L39: =L38+J39-K39 -> 80285
C40: 30/6/2026 | D40: ابو عطيه | E40: 2103000 | G40: =G39+E40-F40 -> 17363045 | H40: 46061 | I40: جادو | J40: 2000 | L40: =L39+J40-K40 -> 82285
C41: 46029 | D41: توريد دروب | F41: 15000000 | G41: =G40+E41-F41 -> 2363045 | H41: 46150 | I41: سعفان | J41: 1000 | L41: =L40+J41-K41 -> 83285
C42: 46029 | D42: محمد عبد الله | E42: 853000 | G42: =G41+E42-F42 -> 3216045 | H42: 46181 | I42: عادل نصار | J42: 1500 | L42: =L41+J42-K42 -> 84785
...

Sheet مدفوعات التحالف
C2: مدفوعات مصطفي ياسين للتحالف
C4: التاريخ | D4: البيان | E4: المدفوعات | F4: المدفوعات $
D5: رصيد | E5: 76541667
C6: 25/6/2026 | D6: طيران البراق طرابلس | E6: 796470
C7: 24/6/2026 | D7: بند استثمار | E7: 5000000
C8: 27/6/2026 | D8: استثمار | E8: 5000000
C9: 28/6/2026 | D9: توريد دروب | E9: 10000000
C10: 28/6/2026 | D10: مصر للطيران | E10: 1700000
C11: 28/6/2026 | D11: استثمار | E11: 5000000
C12: 28/6/2026 | D12: استثمار | E12: 5000000
C13: 28/6/2026 | D13: دروب محمد يوسف | E13: 72000
C14: 30/6/2026 | D14: الافريقيه | E14: 2000000
C15: 30/6/2026 | D15: دروب حساب اشرف شيحه | E15: 1332000
C16: 46029 | D16: دروب حساب احمد غزي | E16: 1891500
C17: 46029 | D17: دروب من حساب خالد نجيب | E17: 126050
C18: 46029 | D18: توريد لدروب | E18: 15000000
C19: 46029 | D19: لاكي تورز | E19: 9690000
C20: 46060 | D20: لخيري استثمار | E20: 5000000
C21: 46060 | D21: الحج حماده | E21: 2400000
C22: 46060 | D22: الحج حماده | E22: 3000000
C23: 46060 | D23: اسامه خليفه | E23: 3000000
C24: 46060 | D24: خيري | E24: 5100000
C25: 46060 | D25: مدفوعه للتحالف | E25: 3000000
C26: 46149 | D26: توريد لدروب | E26: 7000000
C27: 46149 | D27: تسليم للافريقيه | E27: 1000000
... C40: 46333 | D40: توريد لدروب | E40: 12000000
C41: 13/7/2026 | D41: مدفوعه للاكي | E41: 2486333
C42: 13/7/2026 | D42: مدفوعه للاستثمار | E42: 4000000
C43: 14/7/2026 | D43: مدفوعه للتحالف | E43: 5000000
C44: 14/7/2026 | D44: مدفوعه للافريقيه | E44: 900000
C45: 19/7/2026 | D45: التحالف دروب | E45: 10000000
C46: 19/7/2026 | D46: مدفوعه للبراق | E46: 400000
C47: 19/7/2026 | D47: مصر للطيران | E47: 1000000
C48: 19/7/2026 | D48: الافريقيه | E48: 1500000
C49: 19/7/2026 | D49: مدفوعه للتحالف | E49: 8000000
C50: 20/7/2026 | D50: مدفوعه للتحالف | E50: 6000000
C51: 21/7/2026 | D51: مدفوعه للتحالف | E51: 4400000
C52: 46333 | E52: 1907000
C53: 21/7/2026 | D53: البراق طرابلس | E53: 350000
C54: 21/7/2026 | D54: عمرو الليبيه | E54: 2000000
...

Sheet المليجي
A1: الاسم | B1: تاريخ الميلاد | C1: الرقم القومي | D1: رقم الجواز | E1: المنفذ | F1: جهة السفر | G1: شركة الطيران | H1: تاريخ المغادرة | I1: ميعاد المغادرة | J1: الوكيل | K1: مورد الاستثمار | L1: ملاحظات | M1: نوع الخدمه | N1: ملاحظات | O1: ملاحظات | P1: ملاحظات | Q1: مدين دولار | R1: دائن دولار | S1: مدين مصري | T1: دائن مصري
A2: ما قبله | Q2: 0 | R2: 0 | S2: 913687 | T2: 0
A3: سفر 22 يونيو طيران وبري
A4: ياسر محمد احمد احمد | B4: 1997-09-03 | C4: 29703092301699 | D4: A30517163 | E4: مطار القاهره | F4: طرابلس | G4: البراق | H4: 2026-06-22 | I4: 0.41666667 | J4: المليجي | L4: بالغ | M4: خدمه احاديه (م فقط) | S4: 18000
A5: قايد محمد قايد محمد | B5: 1971-11-15 | C5: 27111152600796 | D5: A44619571 | E5: مطار القاهره | F5: طرابلس | G5: الافريقيه | H5: 2026-06-22 | I5: 0.41666667 | J5: المليجي | L5: بالغ | M5: خدمه ثنائيه (م+ت) | S5: 26000
A6: محمود حمدي احمد احمد | B6: 36541 | C6: 300001162301358 | D6: A30913599 | E6: مطار القاهره | F6: طرابلس | G6: البراق | H6: 2026-06-22 | I6: 0.41666667 | J6: المليجي | L6: بالغ | M6: خدمه احاديه (م فقط) | S6: 18000
A7: عباس قعود عباس ابو رحاب | B7: 1969-12-06 | C7: 26912062600818 | D7: A44619592 | E7: مطار القاهره | F7: طرابلس | G7: الافريقيه | H7: 2026-06-22 | I7: 0.41666667 | J7: المليجي | L7: بالغ | M7: خدمه ثنائيه (م+ت) | S7: 26000
A8: سامح جمال احمد محمد | B8: 1988-11-25 | C8: 28811252300892 | D8: A27376783 | E8: مطار القاهره | F8: طرابلس | G8: البراق | H8: 2026-06-22 | I8: 0.60416667 | J8: المليجي | L8: بالغ | M8: خدمه احاديه (م فقط) | S8: 18000
A9: تذاكر رحله 12 يونيو التاج بنغازي من البرج عدد 1*8000 | S9: 8000
A10: تذاكر رحله 16 يونيو الليبيه طرابلس القاهره عدد 1*8700 | S10: 8700
A11: تذاكر رحله اير ليبيا بنغازي البرج 1*10550 | S11: 10550
A12: سفر يوم 23 يونيو
A13: ناصر احمد محمد عبدالحميد | B13: 1997-02-14 | C13: 29702142300099 | D13: A37332045 | E13: مطار القاهره | F13: مصراته | G13: مصر للطيران | H13: 2026-06-23 | I13: 0.79513889 | J13: المليجي | L13: بالغ | M13: خدمه ثنائيه (م+ت) | S13: 26000
A14: رمضان احمد محمد محبوب | B14: 1974-10-27 | C14: 27410272300556 | D14: A43740403 | E14: مطار القاهره | F14: طرابلس | G14: تاج | H14: 2026-06-23 | I14: 0.41666667 | J14: المليجي | L14: بالغ | M14: خدمه احاديه (م فقط) | S14: 18000
A16: مجدى سالم بشير احشاد | B16: 1981-07-16 | C16: 46194 | D16: AA836163 | E16: مطار القاهره | F16: كيب تاون/اديس ابابا | G16: الاثيوبيه ET 452 | H16: AA836163 | I16: 0.086805556 | J16: المليجي | L16: تاشيره فوريه | M16: ليبي | Q16: 400
A17: سفر يوم 24 يونيو | W17: 46197
A18: محمود حمدى خليفه خليل | B18: 1995-09-30 | C18: 29509302302773 | D18: A44632979 | E18: مطار القاهره | F18: بنغازى | G18: الافريقيه | H18: 2026-06-24 | I18: 0.49652778 | J18: المليجي | L18: بالغ | M18: خدمه ثلاثيه | S18: 43725
A19: محمد رمضان عبد المعطى عبد المعطى | B19: 1991-04-15 | C19: 29104152300998 | D19: A40990829 | E19: مطار القاهره | F19: طرابلس | G19: اويا | H19: 2026-06-24 | I19: 0.52083333 | J19: المليجي | L19: بالغ | M19: خدمه احاديه (م فقط) | S19: 18000
A20: محمود مخلف محمود محمد | B20: 1985-04-30 | C20: 28504302300457 | D20: A04317233 | E20: مطار القاهره | F20: طرابلس | G20: اويا | H20: 2026-06-24 | I20: 0.52083333 | J20: المليجي | L20: بالغ | M20: خدمه احاديه (م فقط) | S20: 18000
A21: سيف خلف احمد عباس | B21: 1973-01-06 | C21: 27301062300452 | D21: A44403944 | E21: مطار القاهره | F21: طرابلس | G21: اير كايرو | H21: 2026-06-24 | I21: 0.52430556 | J21: المليجي | L21: بالغ | M21: خدمه احاديه (م فقط) | S21: 18000
A22: على احمد محمد عبدالنبي | B22: 1978-02-04 | C22: 27802042301095 | D22: A44643412 | E22: مطار القاهره | F22: طرابلس | G22: اير كايرو | H22: 2026-06-24 | I22: 0.52430556 | J22: المليجي | L22: بالغ | M22: خدمه احاديه (م فقط) | S22: 18000
A23: سعيد شعبان رمضان سالم | B23: 1976-11-24 | C23: 27611242301057 | D23: A44952444 | E23: مطار القاهره | F23: طرابلس | G23: اير كايرو | H23: 2026-06-24 | I23: 0.52430556 | J23: المليجي | L23: بالغ | M23: خدمه احاديه (م فقط) | S23: 18000
A24: سفر يوم 25 يونيو
A25: محروس حميده عبد العزيز عبد النبي | B25: 1974-04-19 | C25: 27404192300598 | D25: A45383831 | E25: مطار القاهره | F25: مصراته | G25: الافريقيه | H25: 2026-06-25 | I25: 0.75 | J25: المليجي | L25: بالغ | M25: خدمه ثنائيه (م+ت) | N25: 26000 | S25: 26000
A26: امير محمد شعبان محمد | B26: 2002-10-01 | C26: 30210012312775 | D26: A44957161 | E26: منفذ السلوم | F26: بنغازى | G26: اتوبيس | H26: 2026-06-25 | I26: 0.95833333 | J26: المليجي | L26: بالغ | M26: خدمه ثنائيه (م+ا) | N26: 38750 | S26: 38750
A27: صابر سعيد صابر عبد التواب | B27: 1996-01-07 | C27: 29601072300354 | D27: A44944541 | E27: منفذ السلوم | F27: بنغازى | G27: اتوبيس | H27: 2026-06-25 | I27: 0.95833333 | J27: المليجي | L27: بالغ | M27: خدمه ثنائيه (م+ا) | N27: 38750 | S27: 38750
A28: رجب جمعه عطيه عبد التواب | B28: 1991-04-03 | C28: 29104032300439 | D28: A44405431 | E28: منفذ السلوم | F28: بنغازى | G28: اتوبيس | H28: 2026-06-25 | I28: 0.95833333 | J28: المليجي | L28: بالغ | M28: خدمه ثنائيه (م+ا) | N28: 38750 | S28: 38750
A29: عاشور جمعه عطيه عبد التواب | B29: 1995-08-21 | C29: 29508212301194 | D29: A44405430 | E29: منفذ السلوم | F29: بنغازى | G29: اتوبيس | H29: 2026-06-25 | I29: 0.95833333 | J29: المليجي | L29: بالغ | M29: خدمه ثنائيه (م+ا) | N29: 38750 | S29: 38750
A30: حسين حسين الباهي محمد | B30: 1983-08-16 | C30: 28308162300474 | D30: A33118893 | E30: منفذ السلوم | F30: بنغازى | G30: اتوبيس | H30: 2026-06-25 | I30: 0.95833333 | J30: المليجي | L30: بالغ | M30: خدمه ثنائيه (م+ا) | N30: 38750 | S30: 38750
A31: محمد فتحى سلومه صالح | B31: 1996-01-10 | C31: 29601102303116 | D31: A44639480 | E31: منفذ السلوم | F31: بنغازى | G31: اتوبيس | H31: 2026-06-25 | I31: 0.95833333 | J31: المليجي | L31: بالغ | M31: خدمه ثنائيه (م+ا) | N31: 38750 | S31: 38750
A32: سالم رجب سالم احمد | B32: 1985-07-01 | C32: 28507012302838 | D32: A45156841 | E32: منفذ السلوم | F32: بنغازى | G32: اتوبيس | H32: 2026-06-25 | I32: 0.95833333 | J32: المليجي | L32: بالغ | M32: خدمه ثنائيه (م+ا) | N32: 38750 | S32: 38750
A33: عبد العظيم شعبان عبد العظيم جاد المولى | B33: 1994-11-21 | C33: 29411212300437 | D33: A04568100 | E33: منفذ السلوم | F33: بنغازى | G33: اتوبيس | H33: 2026-06-25 | I33: 0.95833333 | J33: المليجي | L33: بالغ | M33: خدمه ثنائيه (م+ا) | N33: 38750 | S33: 38750
A34: احمد تمام عبد المنعم عبد الجواد | B34: 1995-08-05 | C34: 29508052202119 | D34: A26576493 | E34: منفذ السلوم | F34: بنغازى | G34: اتوبيس | H34: 2026-06-25 | I34: 0.95833333 | J34: المليجي | L34: بالغ | M34: خدمه ثنائيه (م+ا) | N34: 38750 | S34: 38750
A35: عرفه على سلمان ناصف | B35: 2003-02-16 | C35: 30302162300955 | D35: A44955794 | E35: منفذ السلوم | F35: بنغازى | G35: اتوبيس | H35: 2026-06-25 | I35: 0.95833333 | J35: المليجي | L35: بالغ | M35: خدمه ثنائيه (م+ا) | N35: 38750 | S35: 38750
A36: ايداع بنكي بتاريخ 28 يونيو | T36: 2380000
A37: ايداع بنكي بتاريخ 28 يونيو | T37: 210223
A38: سفر 26&27 يونيو
A39: سفر يوم 26 يونيو
A40: احمد السيد عبد الشفيق عبد الرحمن | B40: 1990-09-11 | C40: 29009112300372 | D40: A44642943 | E40: مطار برج العرب | F40: بنغازى | G40: الافريقيه | H40: 2026-06-26 | I40: 0.125 | J40: المليجي | L40: بالغ | M40: خدمه ثلاثيه | S40: 43225
A41: احمد خالد عبد الله حافظ | B41: 2007-10-09 | C41: 30710092301496 | D41: A45130851 | E41: مطار برج العرب | F41: بنغازى | G41: الافريقيه | H41: 2026-06-26 | I41: 0.125 | J41: المليجي | L41: بالغ | M41: خدمه ثلاثيه | S41: 43225
...

Sheet رضا
A1: الاسم | B1: تاريخ الميلاد | C1: الرقم القومي | D1: رقم الجواز | E1: المنفذ | F1: جهة السفر | G1: شركة الطيران | H1: تاريخ المغادرة | I1: ميعاد المغادرة | J1: الوكيل | K1: مورد الاستثمار | L1: ملاحظات | M1: نوع الخدمه | N1: ملاحظات | O1: ملاحظات | P1: ملاحظات | Q1: مدين دولار | R1: دائن دولار | S1: مدين مصري | T1: دائن مصري
A2: ما قبله | S2: 0 | T2: 0
A3: تقديم 11 اغسطس
A4: محمد فرج مختار داود | B4: 1987-02-01 | C4: 28702011203531 | D4: A45612841 | E4: مطار برج العرب | F4: بنغازى | G4: اير ليبيا TLR 150 | H4: 2026-08-12 | I4: 0.33333333 | J4: رضا | L4: بالغ | M4: خدمه ثلاثيه | S4: 43225
A5: محمد محمد محمد احمد | B5: 1983-08-15 | C5: 28308152503211 | D5: A41687540 | E5: مطار برج العرب | F5: بنغازى | G5: اير ليبيا TLR 150 | H5: 2026-08-12 | I5: 0.33333333 | J5: رضا | L5: بالغ | M5: خدمه ثلاثيه | S5: 43225
A6: شفيق محمد شفيق عبد المعز محمد | B6: 2000-09-28 | C6: 30009281500033 | D6: A45848861 | E6: مطار برج العرب | F6: بنغازى | G6: اير ليبيا TLR 150 | H6: 2026-08-12 | I6: 0.33333333 | J6: رضا | L6: بالغ | M6: خدمه ثلاثيه | S6: 43225
A7: محمد احمد عطيه صديق | B7: 2008-06-04 | C7: 20806042600996 | D7: A36407577 | E7: مطار برج العرب | F7: بنغازى | G7: اير ليبيا TLR 150 | H7: 2026-08-12 | I7: 0.33333333 | J7: رضا | L7: بالغ | M7: خدمه ثلاثيه | S7: 43225
A8: مهاب محمد يوسف محمد نصار | B8: 1996-06-11 | C8: 29606118800278 | D8: A31611034 | E8: مطار برج العرب | F8: بنغازى | G8: اير ليبيا TLR 150 | H8: 2026-08-12 | I8: 0.33333333 | J8: رضا | L8: بالغ | M8: خدمه ثلاثيه | S8: 43225
A9: بشرى ذكى مبروك السيد حمزه | B9: 1979-06-15 | C9: 27906151800247 | D9: A42683532 | E9: مطار برج العرب | F9: بنغازى | G9: اير ليبيا TLR 150 | H9: 2026-08-12 | I9: 0.33333333 | J9: رضا | L9: انثى | M9: خدمه ثلاثيه | S9: 43225
A10: ياسر عبد الله احمد القطب شتا | B10: 2004-06-01 | C10: 30406011600515 | D10: A44878743 | E10: مطار برج العرب | F10: بنغازى | G10: اير ليبيا TLR 150 | H10: 2026-08-12 | I10: 0.33333333 | J10: رضا | L10: بالغ | M10: خدمه ثلاثيه | S10: 43225
A11: علاء حسن حسنين عيسى | B11: 1990-09-02 | C11: 29009021400935 | D11: A45652568 | E11: مطار برج العرب | F11: بنغازى | G11: اير ليبيا TLR 150 | H11: 2026-08-12 | I11: 0.33333333 | J11: رضا | L11: بالغ | M11: خدمه ثلاثيه | S11: 43225
A12: محمد السيد سليمان محمد | B12: 1986-11-28 | C12: 28611282500137 | D12: A45999417 | E12: مطار برج العرب | F12: بنغازى | G12: اير ليبيا TLR 150 | H12: 2026-08-12 | I12: 0.33333333 | J12: رضا | L12: بالغ | M12: خدمه ثلاثيه | S12: 43225
A13: على عبد الله عبد اللاه على | B13: 1984-08-16 | C13: 28408160104613 | D13: A45727845 | E13: مطار برج العرب | F13: بنغازى | G13: اير ليبيا TLR 150 | H13: 2026-08-12 | I13: 0.33333333 | J13: رضا | L13: بالغ | M13: خدمه ثلاثيه | S13: 43225
A14: محمد اسماعيل فرغلى شهاب الدين | B14: 2005-11-16 | C14: 30511162502971 | D14: A45567807 | E14: مطار برج العرب | F14: بنغازى | G14: اير ليبيا TLR 150 | H14: 2026-08-12 | I14: 0.33333333 | J14: رضا | L14: بالغ | M14: خدمه ثلاثيه | S14: 43225
A15: عبد الله عبد الفتاح عبد الله محمد على | B15: 1995-04-01 | C15: 29504011503834 | D15: A31919885 | E15: مطار برج العرب | F15: بنغازى | G15: اير ليبيا TLR 150 | H15: 2026-08-12 | I15: 0.33333333 | J15: رضا | L15: بالغ | M15: خدمه ثلاثيه | S15: 43225
... A52: شريف على حسين خلف الله | B52: 1998-01-20 | C52: 29801202402676 | D52: A29019659 | E52: مطار برج العرب | F52: بنغازى | G52: اير ليبيا TLR 150 | H52: 2026-08-12 | I52: 0.33333333 | J52: رضا | L52: بالغ | M52: خدمه ثلاثيه | S52: 43225
A53: تقديم 12 اغسطس
A54: عطيه صابر عبد الرسول عبد الفضيل | B54: 1998-05-01 | C54: 29805011504431 | D54: A456441297 | E54: مطار برج العرب | F54: بنغازى | G54: اير ليبيا 7Q 148 | H54: 2026-08-13 | I54: 0.70833333 | J54: رضا | L54: بالغ | M54: خدمه ثلاثيه | S54: 43225
A55: ناصر مرسى احمد مرسى | B55: 1978-10-28 | C55: 27810282300391 | D55: A45885888 | E55: مطار برج العرب | F55: بنغازى | G55: اير ليبيا 7Q 148 | H55: 2026-08-13 | I55: 0.70833333 | J55: رضا | L55: بالغ | M55: خدمه ثلاثيه | S55: 43225
A56: محمد ابراهيم عبد المولى معجوز | B56: 1996-04-23 | C56: 29604231600517 | D56: A41790906 | E56: مطار برج العرب | F56: بنغازى | G56: اير ليبيا 7Q 148 | H56: 2026-08-13 | I56: 0.70833333 | J56: رضا | L56: بالغ | M56: خدمه ثلاثيه | S56: 43225
A57: محمود السيد عباس عباس الغزاوى | B57: 2007-11-18 | C57: 30711181601653 | D57: A45645430 | E57: مطار برج العرب | F57: بنغازى | G57: اير ليبيا 7Q 148 | H57: 2026-08-13 | I57: 0.70833333 | J57: رضا | L57: بالغ | M57: خدمه ثلاثيه | S57: 43225
A58: محمد السيد محمد ابراهيم | B58: 1988-07-20 | C58: 28807201202538 | D58: 424940682 | E58: مطار برج العرب | F58: بنغازى | G58: اير ليبيا 7Q 148 | H58: 2026-08-13 | I58: 0.70833333 | J58: رضا | L58: بالغ | M58: خدمه ثلاثيه | S58: 43225
A59: السيد محمد السيد محمد ابراهيم | B59: 2011-08-11 | C59: 31108111202974 | D59: A39266353 | E59: مطار برج العرب | F59: بنغازى | G59: اير ليبيا 7Q 148 | H59: 2026-08-13 | I59: 0.70833333 | J59: رضا | L59: بالغ | M59: خدمه ثلاثيه | S59: 43225
A60: محمد فاروق بليغ جاد المولى | B60: 1984-11-11 | C60: 28411112500419 | D60: A34056336 | E60: مطار برج العرب | F60: بنغازى | G60: اير ليبيا 7Q 148 | H60: 2026-08-13 | I60: 0.70833333 | J60: رضا | L60: بالغ | M60: خدمه ثلاثيه | S60: 43225
A61: مؤمن محمد عبد القوى الاحول | B61: 1984-10-01 | C61: 28410012304594 | D61: A45413826 | E61: مطار برج العرب | F61: بنغازى | G61: اير ليبيا 7Q 148 | H61: 2026-08-13 | I61: 0.70833333 | J61: رضا | L61: بالغ | M61: خدمه ثلاثيه | S61: 43225
A62: محمد ياسر محمد احمد | B62: 1996-09-17 | C62: 29609172300174 | D62: A45141441 | E62: مطار برج العرب | F62: بنغازى | G62: اير ليبيا 7Q 148 | H62: 2026-08-13 | I62: 0.70833333 | J62: رضا | L62: بالغ | M62: خدمه ثلاثيه | S62: 43225
A63: سعد رجب عبد الرحمن عيسى الفيومى | B63: 1984-03-10 | C63: 28403101503197 | D63: A45831644 | E63: مطار برج العرب | F63: بنغازى | G63: اير ليبيا 7Q 148 | H63: 2026-08-13 | I63: 0.70833333 | J63: رضا | L63: بالغ | M63: خدمه ثلاثيه | S63: 43225
A64: محمد احمد عبد اللطيف عبد المقصود عبد الغفار | B64: 2008-12-24 | C64: 30812241500151 | D64: A44173043 | E64: مطار برج العرب | F64: بنغازى | G64: اير ليبيا 7Q 148 | H64: 2026-08-13 | I64: 0.70833333 | J64: رضا | L64: بالغ | M64: خدمه ثلاثيه | S64: 43225
A65: زياد عمر محمد قطرى | B65: 1999-10-01 | C65: 29910011834715 | D65: A45837919 | E65: مطار برج العرب | F65: بنغازى | G65: اير ليبيا 7Q 148 | H65: 2026-08-13 | I65: 0.70833333 | J65: رضا | L65: بالغ | M65: خدمه ثلاثيه | S65: 43225
... A87: احمد الحاج عباس ابراهيم ابو المعاطى | B87: 1997-09-01 | C87: 29709011502294 | D87: A04585924 | E87: مطار برج العرب | F87: بنغازى | G87: اير ليبيا TLR 150 | H87: 2026-08-12 | I87: 0.29166667 | J87: رضا | L87: بالغ | M87: خدمه ثلاثيه | S87: 43225
A88: سداد في حسابات دروب | T88: 3548250
A89: تقفيل | T89: 39425
I107: اجمالي المديونيه دولار | J107: =SUM(Q:Q)-SUM(R:R) -> 0
I108: اجمالي المديونيه مصري | J108: =SUM(S:S)-SUM(T:T) -> 0
I109: الرئيسيه

Sheet منصور
A1: الاسم | B1: تاريخ الميلاد | C1: الرقم القومي | D1: رقم الجواز | E1: المنفذ | F1: جهة السفر | G1: شركة الطيران | H1: تاريخ المغادرة | I1: ميعاد المغادرة | J1: الوكيل | K1: مورد الاستثمار | L1: ملاحظات | M1: نوع الخدمه | N1: ملاحظات | O1: ملاحظات | P1: ملاحظات | Q1: مدين دولار | R1: دائن دولار | S1: مدين مصري | T1: دائن مصري
A2: ما قبله | Q2: 0 | R2: 0 | T2: 1706643
A3: سفر 22 يونيو طيران وبري
A4: على زارع على مبارك | B4: 1997-09-24 | C4: 29709242201131 | D4: A38095421 | E4: منفذ السلوم | F4: بنغازى | G4: اتوبيس | H4: 2026-06-22 | I4: 0.41666667 | J4: منصور | L4: بالغ | M4: خدمه ثنائيه (م+ا) | S4: 38750
A5: طارق يحى زكريا راشد | B5: 1993-10-01 | C5: 29310011103357 | D5: A39456682 | E5: منفذ السلوم | F5: بنغازى | G5: اتوبيس | H5: 2026-06-22 | I5: 0.41666667 | J5: منصور | L5: بالغ | M5: خدمه ثنائيه (م+ا) | S5: 38750
A6: اسلام حسن عيد حسن | B6: 2005-05-08 | C6: 30505081200814 | D6: A44831301 | E6: منفذ السلوم | F6: بنغازى | G6: اتوبيس | H6: 2026-06-22 | I6: 0.41666667 | J6: منصور | L6: بالغ | M6: خدمه ثنائيه (م+ا) | S6: 38750
A7: محمد محمود عبد التواب محمد | B7: 1999-04-01 | C7: 29904012309355 | D7: A43620541 | E7: منفذ السلوم | F7: بنغازى | G7: اتوبيس | H7: 2026-06-22 | I7: 0.41666667 | J7: منصور | L7: بالغ | M7: خدمه ثنائيه (م+ا) | S7: 38750
A8: ابراهيم المغازي ابراهيم المغازي | B8: 1988-04-20 | C8: 28804201204914 | D8: A29090036 | E8: منفذ السلوم | F8: بنغازى | G8: اتوبيس | H8: 2026-06-22 | I8: 0.41666667 | J8: منصور | L8: بالغ | M8: خدمه ثنائيه (م+ا) | S8: 20750
A9: القطب تيسير عوض القطب | B9: 1995-10-01 | C9: 29510011246556 | D9: A41467318 | E9: منفذ السلوم | F9: بنغازى | G9: اتوبيس | H9: 2026-06-22 | I9: 0.41666667 | J9: منصور | L9: بالغ | M9: خدمه ثنائيه (م+ا) | S9: 20750
A10: محمد يحى زكريا راشد | B10: 1998-10-29 | C10: 29810291100059 | D10: A35204095 | E10: منفذ السلوم | F10: بنغازى | G10: اتوبيس | H10: 2026-06-22 | I10: 0.41666667 | J10: منصور | L10: بالغ | M10: خدمه ثنائيه (م+ا) | S10: 38750
A11: عبد الحميد عثمان على عبد الحميد | B11: 1984-09-08 | C11: 28409082301837 | D11: A44650908 | E11: منفذ السلوم | F11: بنغازى | G11: اتوبيس | H11: 2026-06-22 | I11: 0.41666667 | J11: منصور | L11: بالغ | M11: خدمه ثنائيه (م+ا) | S11: 38750
A12: احمد رمضان محمد على | B12: 1998-09-02 | C12: 29809022300779 | D12: A29377744 | E12: منفذ السلوم | F12: بنغازى | G12: اتوبيس | H12: 2026-06-22 | I12: 0.41666667 | J12: منصور | L12: بالغ | M12: خدمه ثنائيه (م+ا) | S12: 38750
A13: محمود عزت عبد الله ابو العلا طلبه | B13: 2007-03-11 | C13: 30703112101638 | D13: A44661267 | E13: منفذ السلوم | F13: بنغازى | G13: اتوبيس | H13: 2026-06-22 | I13: 0.41666667 | J13: منصور | L13: بالغ | M13: خدمه ثنائيه (م+ا) | S13: 38750
A14: اسلام نشأت عبد المنعم الدسوقى خضر | B14: 2007-10-01 | C14: 30710011236032 | D14: A43514823 | E14: منفذ السلوم | F14: بنغازى | G14: اتوبيس | H14: 2026-06-22 | I14: 0.41666667 | J14: منصور | L14: بالغ | M14: خدمه ثنائيه (م+ا) | S14: 38750
A15: جمعه عبدالعاطي ابو سيف حسن حسين | B15: 1999-06-07 | C15: 29906072201475 | D15: A40997609 | E15: منفذ السلوم | F15: بنغازى | G15: اتوبيس | H15: 2026-06-22 | I15: 0.41666667 | J15: منصور | L15: بالغ | M15: خدمه ثنائيه (م+ا) | S15: 38750
... A42: محمد محمد علي السيد ابراهيم | B42: 1978-01-28 | C42: 27801281201659 | D42: A44811052 | E42: مطار برج العرب | F42: طرابلس | G42: الليبيه | H42: 2026-06-22 | I42: 0.95833333 | J42: منصور | L42: بالغ | M42: خدمه ثنائيه (م+ت) | S42: 18000
A43: تسليم ليد احمد بتاريخ 25 يونيو | T43: 532000
A44: تذاكر الليبيه بنغازي البرج بتاريخ 10 يونيو 4*7250 | S44: =4*7250 -> 29000
A45: فرق سعر تذكره البراق طرابلس القاهره بتاريخ 13 يونيو 1*800 | S45: 800
A46: تذاكر التاج بنغازي البرج بتاريخ 14 يونيو 1*8000 | S46: 8000
A47: تذاكر الليبيه بنغازي البرج بتاريخ 17 يونيو 2*10550 | S47: =2*10550 -> 21100
A48: سفر يوم 23 يونيو
A49: احمد حمدي محمد علي السيد | B49: 1986-01-10 | C49: 28610011346934 | D49: A37004643 | E49: منفذ السلوم | F49: بنغازى | G49: اتوبيس | H49: 2026-06-23 | I49: 0.41666667 | J49: منصور | L49: بالغ | M49: خدمه ثنائيه (م+ا) | S49: 38750
A50: باسم يونس عبدالغني محمد | B50: 1995-07-21 | C50: 29507212400579 | D50: A44139912 | E50: منفذ السلوم | F50: بنغازى | G50: اتوبيس | H50: 2026-06-23 | I50: 0.41666667 | J50: منصور | L50: بالغ | M50: خدمه ثنائيه (م+ا) | S50: 38750
A51: عقيله فرج عمار عبدالله | B51: 1976-09-10 | C51: 27610092401213 | D51: A44138475 | E51: منفذ السلوم | F51: بنغازى | G51: اتوبيس | H51: 2026-06-23 | I51: 0.41666667 | J51: منصور | L51: بالغ | M51: خدمه ثنائيه (م+ا) | S51: 38750
A52: عبدالناصر نوح طرفايه ابو سيف | B52: 1986-07-08 | C52: 28601082403514 | D52: A32889134 | E52: منفذ السلوم | F52: بنغازى | G52: اتوبيس | H52: 2026-06-23 | I52: 0.41666667 | J52: منصور | L52: بالغ | M52: خدمه ثنائيه (م+ا) | S52: 38750
A53: عبدالله دياب شليل سنوسي | B53: 1997-01-05 | C53: 29705012412838 | D53: A30555929 | E53: منفذ السلوم | F53: بنغازى | G53: اتوبيس | H53: 2026-06-23 | I53: 0.41666667 | J53: منصور | L53: بالغ | M53: خدمه ثنائيه (م+ا) | S53: 38750
A54: هيثم يونس عبدالغني محمد | B54: 2000-04-01 | C54: 30001042402215 | D54: A33928538 | E54: منفذ السلوم | F54: بنغازى | G54: اتوبيس | H54: 2026-06-23 | I54: 0.41666667 | J54: منصور | L54: بالغ | M54: خدمه ثنائيه (م+ا) | S54: 38750
A55: جابر يونس فراج سليمان | B55: 1986-04-01 | C55: 28601042500851 | D55: A40278225 | E55: منفذ السلوم | F55: بنغازى | G55: اتوبيس | H55: 2026-06-23 | I55: 0.41666667 | J55: منصور | L55: بالغ | M55: خدمه ثنائيه (م+ا) | S55: 38750
A56: عبد العظيم محمود عبدالعظيم محمد بشندي | B56: 1983-10-24 | C56: 28310241700377 | D56: A44909441 | E56: منفذ السلوم | F56: بنغازى | G56: اتوبيس | H56: 2026-06-23 | I56: 0.41666667 | J56: منصور | L56: بالغ | M56: خدمه ثنائيه (م+ا) | S56: 38750
A57: وليد على محمود روبي | B57: 1985-05-03 | C57: 28505032401295 | D57: A34365878 | E57: منفذ السلوم | F57: بنغازى | G57: اتوبيس | H57: 2026-06-23 | I57: 0.41666667 | J57: منصور | L57: بالغ | M57: خدمه ثنائيه (م+ا) | S57: 38750
A58: عطيه محمد ابراهيم عبداللطيف | B58: 1989-08-27 | C58: 28908272402059 | D58: A43647295 | E58: منفذ السلوم | F58: بنغازى | G58: اتوبيس | H58: 2026-06-23 | I58: 0.41666667 | J58: منصور | L58: بالغ | M58: خدمه ثنائيه (م+ا) | S58: 18000
A59: ايمن ابراهيم محمد ابراهيم | B59: 1994-01-30 | C59: 29401302402071 | D59: A37912489 | E59: منفذ السلوم | F59: بنغازى | G59: اتوبيس | H59: 2026-06-23 | I59: 0.41666667 | J59: منصور | L59: بالغ | M59: خدمه ثنائيه (م+ا) | S59: 38750
A60: رضا فرج عبدالغني منصور | B60: 1990-05-07 | C60: 29005072403194 | D60: A34446539 | E60: منفذ السلوم | F60: بنغازى | G60: اتوبيس | H60: 2026-06-23 | I60: 0.41666667 | J60: منصور | L60: بالغ | M60: خدمه ثنائيه (م+ا) | S60: 38750
... A74: محمود رضا حامد محمدين | B74: 1992-12-19 | C74: 29212192402138 | D74: A39620882 | E74: مطار القاهره | F74: مصراته | G74: البرنيق | H74: 2026-06-23 | I74: 0.95833333 | J74: منصور رافع | L74: بالغ | M74: خدمه احاديه (م فقط) | S74: 18000
A75: تسليم ليد احمد بتاريخ27 يونيو | T75: 619000
A76: سفر يوم 24 يونيو
A77: محمد ابراهيم ابراهيم مسعد فوده | B77: 1984-06-19 | C77: 28406191200251 | D77: A41735956 | E77: منفذ السلوم | F77: بنغازى | G77: اتوبيس | H77: 2026-06-24 | I77: 0.41666667 | J77: منصور | L77: بالغ | M77: خدمه ثنائيه (م+ا) | S77: 38750
A78: الاء محمد ناجي عبدالعليم ابراهيم | B78: 2017-12-09 | C78: 31712092404941 | D78: A43631479 | E78: مطار القاهره | F78: بنغازى | G78: الافريقيه | H78: 2026-06-24 | I78: 0.49652778 | J78: منصور رافع | L78: طفل | M78: خدمه احاديه (م فقط) | S78: 18000
A79: محمد احمد محمد السيد | B79: 1995-09-24 | C79: 29509242301333 | D79: A43644187 | E79: مطار القاهره | F79: بنغازى | G79: الافريقيه | H79: 2026-06-24 | I79: 0.49652778 | J79: منصور رافع | L79: بالغ | M79: خدمه ثلاثيه | S79: 43725
...

Sheet صابر
A1: الاسم | B1: تاريخ الميلاد | C1: الرقم القومي | D1: رقم الجواز | E1: المنفذ | F1: جهة السفر | G1: شركة الطيران | H1: تاريخ المغادرة | I1: ميعاد المغادرة | J1: الوكيل | K1: مورد الاستثمار | L1: ملاحظات | M1: نوع الخدمه | N1: ملاحظات | O1: ملاحظات | P1: ملاحظات | Q1: مدين دولار | R1: دائن دولار | S1: مدين مصري | T1: دائن مصري
A2: ما قبله | Q2: 0 | R2: 0 | T2: 0
A3: تقديم 18 يوليو
A4: محمد عبد الغنى محمد عبد الغنى | B4: 2001-12-06 | C4: 30112061500577 | D4: A28663596 | E4: مطار برج العرب | F4: بنغازى | G4: الليبيه LN 209 | H4: 2026-07-19 | I4: 0.25 | J4: صابر | L4: بالغ | M4: خدمه ثلاثيه | S4: 43425
A5: عبد الحميد السيد مجاهد يونس ابو العنين | B5: 2004-06-20 | C5: 30406201204853 | D5: A44538597 | E5: مطار برج العرب | F5: بنغازى | G5: الليبيه LN 209 | H5: 2026-07-19 | I5: 0.25 | J5: صابر | L5: بالغ | M5: خدمه ثلاثيه | S5: 43425
A6: محمد شعبان احمد حبيب | B6: 1986-06-26 | C6: 28606262300871 | D6: A45404936 | E6: مطار برج العرب | F6: بنغازى | G6: الليبيه LN 209 | H6: 2026-07-19 | I6: 0.25 | J6: صابر | L6: بالغ | M6: خدمه ثلاثيه | S6: 43425
A7: احمد عبد الرحمن مسعود ابراهيم | B7: 1994-06-28 | C7: 29406280201613 | D7: A45335013 | E7: مطار برج العرب | F7: بنغازى | G7: الليبيه LN 209 | H7: 2026-07-19 | I7: 0.25 | J7: صابر | L7: بالغ | M7: خدمه ثلاثيه | S7: 43425
A8: ليان احمد عبد الرحمن مسعود ابراهيم | B8: 2024-09-17 | C8: 32409170202241 | D8: A45269911 | E8: مطار برج العرب | F8: بنغازى | G8: الليبيه LN 209 | H8: 2026-07-19 | I8: 0.25 | J8: صابر | L8: رضيع | M8: خدمه ثلاثيه | S8: 20200
A9: ابراهيم رشدى السيد على الكلاف | B9: 2008-08-01 | C9: 108059 | D9: A44922562 | E9: مطار برج العرب | F9: بنغازى | G9: الليبيه LN 209 | H9: 2026-07-19 | I9: 0.25 | J9: صابر | L9: بالغ | M9: خدمه ثلاثيه | S9: 43425
A10: عمر انور سويسى عوض شحاته | B10: 2010-02-13 | C10: 31002132403474 | D10: A45408554 | E10: مطار برج العرب | F10: بنغازى | G10: الليبيه LN 209 | H10: 2026-07-19 | I10: 0.25 | J10: صابر | L10: بالغ | M10: خدمه ثلاثيه | S10: 43425
A11: ايداع بنكي بتاريخ 17 يوليو | T11: 50000
A12: ايداع بنكي بتاريخ 19 يوليو | T12: 23000
A13: ايداع بنكي بتاريخ 19 يوليو | T13: 50000
A14: ايداع بنكي بتاريخ 18 يوليو | T14: 70000
A15: ايداع بنكي بتاريخ 17 يوليو | T15: 210000
A16: ايداع بنكي بتاريخ 19 يوليو | T16: 20000
A17: تقديم 19 يوليو
A18: حمدی محمد حسون السيد | B18: 1985-01-02 | C18: 28501021603095 | D18: A32808427 | E18: مطار القاهره | F18: طرابلس | G18: اير كايرو SM 231 | H18: 2026-07-21 | I18: 0.41666667 | J18: صابر | L18: بالغ | M18: خدمه ثنائيه (م+ت) | S18: 26200
A19: ايمن محمد احمد اسماعيل | B19: 1977-05-29 | C19: 27705292602036 | D19: A45548319 | E19: مطار القاهره | F19: طرابلس | G19: اير كايرو SM 231 | H19: 2026-07-21 | I19: 0.41666667 | J19: صابر | L19: بالغ | M19: خدمه ثنائيه (م+ت) | S19: 26200
A20: مصطفى بسيونى عبد اللطيف السناط | B20: 1985-03-09 | C20: 28503091501691 | D20: A36883023 | E20: منفذ السلوم | F20: بنغازى | G20: اتوبيس السلوم | H20: 2026-07-20 | I20: 0.41666667 | J20: صابر | L20: بالغ | M20: خدمه ثنائيه (م+ا) | S20: 38950
A21: اسراء عوض على حسين الباز الزيات | B21: 2005-02-01 | C21: 30502011211984 | D21: A44546599 | E21: منفذ السلوم | F21: بنغازى | G21: اتوبيس السلوم | H21: 2026-07-20 | I21: 0.41666667 | J21: صابر | L21: انثى | M21: خدمه ثنائيه (م+ا) | S21: 28330
A22: مى قطب ابراهيم شتيوى | B22: 2005-04-19 | C22: 30504191600722 | D22: A34907799 | E22: منفذ السلوم | F22: بنغازى | G22: اتوبيس السلوم | H22: 2026-07-20 | I22: 0.41666667 | J22: صابر | L22: انثى | M22: خدمه ثنائيه (م+ا) | S22: 28330
A23: اميره محمد حماده عباس | B23: 2005-01-01 | C23: 30501012622787 | D23: A04395453 | E23: منفذ السلوم | F23: بنغازى | G23: اتوبيس السلوم | H23: 2026-07-20 | I23: 0.41666667 | J23: صابر | L23: انثى | M23: خدمه ثنائيه (م+ا) | S23: 28330
A24: حسناء رضا محمود ابراهيم | B24: 2002-07-31 | C24: 30207312400543 | D24: A34859524 | E24: منفذ السلوم | F24: بنغازى | G24: اتوبيس السلوم | H24: 2026-07-20 | I24: 0.41666667 | J24: صابر | L24: انثى | M24: خدمه ثنائيه (م+ا) | S24: 28330
A25: خلود ممدوح سلامه سليم | B25: 2005-08-30 | C25: 30508301500384 | D25: A34907941 | E25: منفذ السلوم | F25: بنغازى | G25: اتوبيس السلوم | H25: 2026-07-20 | I25: 0.41666667 | J25: صابر | L25: انثى | M25: خدمه ثنائيه (م+ا) | S25: 28330
A26: حماده رشدى عبد القادر محمد | B26: 1996-09-22 | C26: 38105843096092223106257 | D26: A38105843 | E26: منفذ السلوم | F26: بنغازى | G26: اتوبيس السلوم | H26: 2026-07-20 | I26: 0.41666667 | J26: صابر | L26: بالغ | M26: خدمه ثنائيه (م+ا) | S26: 38950
A27: ايداع بنكي بتاريخ 20 يوليو | T27: 50000
A28: ايداع بنكي بتاريخ 20 يوليو | T28: 1000000
A29: تقديم 21 يوليو
A30: محمد ابراهيم الدسوقى الشعيبى | B30: 2009-01-16 | C30: 30901161400299 | D30: A41774989 | E30: مطار برج العرب | F30: بنغازى | G30: اير ليبيا 7Q 148 | H30: 2026-07-22 | I30: 0.33333333 | J30: صابر | L30: بالغ | M30: خدمه ثلاثيه | S30: 43425
A31: محمد فهمى محمد محمد سبوخ | B31: 1983-04-01 | C31: 28304011502835 | D31: A41808619 | E31: مطار القاهره | F31: طرابلس | G31: اير كايرو SM 231 | H31: 2026-07-23 | I31: 0.52430556 | J31: صابر | L31: بالغ | M31: خدمه ثنائيه (م+ت) | S31: 26200
A32: سعيد محمد مصطفى غنومه | B32: 1988-04-25 | C32: 28804251501057 | D32: A45342665 | E32: مطار القاهره | F32: طرابلس | G32: اير كايرو SM 231 | H32: 2026-07-23 | I32: 0.52430556 | J32: صابر | L32: بالغ | M32: خدمه ثنائيه (م+ت) | S32: 26200
A33: احمد سيد عبد العزيز رمضان | B33: 1991-04-20 | C33: 29104202202275 | D33: A44944390 | E33: مطار برج العرب | F33: بنغازى | G33: اير ليبيا 7Q 148 | H33: 2026-07-22 | I33: 0.33333333 | J33: صابر | L33: بالغ | M33: خدمه ثلاثيه | S33: 43425
A34: يوسف محمد عبد السلام محمد نصر | B34: 2010-03-21 | C34: 31003211700073 | D34: A45598071 | E34: مطار برج العرب | F34: بنغازى | G34: اير ليبيا 7Q 148 | H34: 2026-07-22 | I34: 0.33333333 | J34: صابر | L34: بالغ | M34: خدمه ثلاثيه | S34: 43425
A35: محمد البسطويسى محمد البسطويسى | B35: 1988-07-02 | C35: 28807021500271 | D35: A45270075 | E35: مطار برج العرب | F35: بنغازى | G35: اير ليبيا 7Q 148 | H35: 2026-07-22 | I35: 0.33333333 | J35: صابر | L35: بالغ | M35: خدمه ثلاثيه | S35: 43425
A36: محمد محسن محمد عبد اللاه | B36: 2010-06-21 | C36: 31006212200391 | D36: A42258646 | E36: مطار برج العرب | F36: بنغازى | G36: اير ليبيا 7Q 148 | H36: 2026-07-22 | I36: 0.33333333 | J36: صابر | L36: بالغ | M36: خدمه ثلاثيه | S36: 43425
A37: خالد مختار عبد الرحمن عبد المجيد | B37: 1983-11-02 | C37: 28311021401472 | D37: A45675552 | E37: مطار برج العرب | F37: بنغازى | G37: اير ليبيا 7Q 148 | H37: 2026-07-22 | I37: 0.33333333 | J37: صابر | L37: بالغ | M37: خدمه ثلاثيه | S37: 43425
A38: محمد احمد محمد زغلول الودنه | B38: 1990-05-20 | C38: 29005201501777 | D38: A45358973 | E38: مطار القاهره | F38: طرابلس | G38: اير كايرو SM 231 | H38: 2026-07-23 | I38: 0.52430556 | J38: صابر | L38: بالغ | M38: خدمه ثنائيه (م+ت) | S38: 26200
A39: وائل احمد محمد محمد زغلول الودنه | B39: 1984-06-07 | C39: 28406071501355 | D39: A45345703 | E39: مطار القاهره | F39: طرابلس | G39: اير كايرو SM 231 | H39: 2026-07-23 | I39: 0.52430556 | J39: صابر | L39: بالغ | M39: خدمه ثنائيه (م+ت) | S39: 26200
A40: محمد على حسين ضيف | B40: 1990-11-19 | C40: 29011192201099 | D40: A44952416 | E40: مطار برج العرب | F40: بنغازى | G40: اير ليبيا 7Q 148 | H40: 2026-07-22 | I40: 0.33333333 | J40: صابر | L40: بالغ | M40: خدمه ثلاثيه | S40: 43425
...

Sheet شركه هاي لايتس
A1: الاسم | B1: تاريخ الميلاد | C1: الرقم القومي | D1: رقم الجواز | E1: المنفذ | F1: جهة السفر | G1: شركة الطيران | H1: تاريخ المغادرة | I1: ميعاد المغادرة | J1: الوكيل | K1: مورد الاستثمار | L1: ملاحظات | M1: نوع الخدمه | N1: ملاحظات | O1: ملاحظات | P1: ملاحظات | Q1: مدين دولار | R1: دائن دولار | S1: مدين مصري | T1: دائن مصري
A2: ما قبله | Q2: 0 | R2: 0
A3: ايداع بنكي بتاريخ 9 اغسطس باسم بيشوي عبد الملك | T3: 22200
A4: ايداع بنكي بتاريخ 9 اغسطس مصطفي عاصم | T4: 22200
A5: ايداع بنكي بتاريخ 9 اغسطس حازم احمد | T5: 22200
A6: ايداع بنكي بتاريخ 9 اغسطس محمد عبد النبي | T6: 22200
A7: ايداع بنكي بتاريخ 9 اغسطس محمد ممدوح | T7: 22200
A8: ايداع بنكي بتاريخ 9 اغسطس حسام احمد | T8: 22200
A9: تقديم 10 اغسطس
A10: حازم احمد احمد محمد | B10: 1997-02-22 | C10: 29702221400091 | D10: A44906818 | E10: مطار القاهره | F10: بنغازى | G10: مصر للطيران MS 829 | H10: 2026-08-24 | I10: 0.25 | J10: هاي لايتس | L10: بالغ | M10: خدمه احاديه (م فقط) | S10: 22200
A11: حسام احمد ابراهيم سعداوى | B11: 1995-07-01 | C11: 29507011409331 | D11: A40383433 | E11: مطار القاهره | F11: بنغازى | G11: مصر للطيران MS 829 | H11: 2026-08-24 | I11: 0.25 | J11: هاي لايتس | L11: بالغ | M11: خدمه احاديه (م فقط) | S11: 22200
A12: محمد عبد النبى ابراهيم عيد | B12: 1998-06-23 | C12: 29806231700459 | D12: A35411971 | E12: مطار القاهره | F12: بنغازى | G12: مصر للطيران MS 829 | H12: 2026-08-24 | I12: 0.25 | J12: هاي لايتس | L12: بالغ | M12: خدمه احاديه (م فقط) | S12: 22200
A13: محمد ممدوح السيد هاشم | B13: 1988-08-31 | C13: 28808312101796 | D13: A31204305 | E13: مطار القاهره | F13: بنغازى | G13: مصر للطيران MS 829 | H13: 2026-08-24 | I13: 0.25 | J13: هاي لايتس | L13: بالغ | M13: خدمه احاديه (م فقط) | S13: 22200
A14: مصطفى عاصم محمود حمزه | B14: 1993-11-01 | C14: 29311010100636 | D14: A404724779 | E14: مطار القاهره | F14: بنغازى | G14: مصر للطيران MS 829 | H14: 2026-08-24 | I14: 0.25 | J14: هاي لايتس | L14: بالغ | M14: خدمه احاديه (م فقط) | S14: 22200
A15: بيشوى عبد الملك مجلى عبد السيد | B15: 1989-03-21 | C15: 28903212401736 | D15: A28336526 | E15: مطار القاهره | F15: بنغازى | G15: مصر للطيران MS 829 | H15: 2026-08-24 | I15: 0.25 | J15: هاي لايتس | L15: بالغ | M15: خدمه احاديه (م فقط) | S15: 22200
I20: اجمالي المديونيه دولار | J20: =SUM(Q:Q)-SUM(R:R) -> 0
I21: اجمالي المديونيه مصري | J21: =SUM(S:S)-SUM(T:T) -> 0
I22: الرئيسيه

Sheet لاكي
A1: الاسم | B1: تاريخ الميلاد | C1: الرقم القومي | D1: رقم الجواز | E1: المنفذ | F1: جهة السفر | G1: شركة الطيران | H1: تاريخ المغادرة | I1: ميعاد المغادرة | J1: الوكيل | K1: مورد الاستثمار | L1: ملاحظات | M1: نوع الخدمه | N1: ملاحظات | O1: ملاحظات | P1: ملاحظات | Q1: مدين دولار | R1: دائن دولار | S1: مدين مصري | T1: دائن مصري
A2: ما قبله | S2: 0 | T2: 0
A3: استثمار بري 3*425 | Q3: =3*425 -> 1275
A4: تسليم في الشركه 19 اغسطس | R4: 1275
A5: استثمار بري 1*425 | Q5: 425
A6: استثمار بري 3*425 | Q6: =3*425 -> 1275
I11: اجمالي المديونيه دولار | J11: =SUM(Q:Q)-SUM(R:R) -> 1700
I12: اجمالي المديونيه مصري | J12: =SUM(S:S)-SUM(T:T) -> 0
I13: الرئيسيه

Sheet ابو سليم
A1: الاسم | B1: تاريخ الميلاد | C1: الرقم القومي | D1: رقم الجواز | E1: المنفذ | F1: جهة السفر | G1: شركة الطيران | H1: تاريخ المغادرة | I1: ميعاد المغادرة | J1: الوكيل | K1: مورد الاستثمار | L1: ملاحظات | M1: نوع الخدمه | N1: ملاحظات | O1: ملاحظات | P1: ملاحظات | Q1: مدين دولار | R1: دائن دولار | S1: مدين مصري | T1: دائن مصري
A2: ما قبله | S2: 0 | T2: 0
A3: تقديم 19 اغسطس
A4: سالم عيد سالم محمد | B4: 1974-06-15 | C4: 27406151200379 | D4: A28693974 | E4: مطار القاهره | F4: طرابلس | G4: مصر للطيران MS 831 | H4: 2026-08-20 | I4: 0.25 | J4: ابو سليم | L4: بالغ | M4: خدمه احاديه (م فقط) | S4: 22000
A5: توريد نقدي | T5: 26000
A6: تقديم 20 اغسطس
A7: محمد عبد المعطى المتولى سلامه | B7: 1988-09-01 | C7: 28809011222331 | D7: A28218772 | E7: مطار برج العرب | F7: بنغازى | G7: اير ليبيا 7Q 148 | H7: 2026-08-21 | I7: 0.70833333 | J7: ابو سليم | L7: بالغ | M7: خدمه ثلاثيه | S7: 43225
A8: محمد محمود ربيع مصطفى | B8: 1996-08-11 | C8: 29608111201614 | D8: A29397371 | E8: مطار برج العرب | F8: بنغازى | G8: اير ليبيا 7Q 148 | H8: 2026-08-21 | I8: 0.70833333 | J8: ابو سليم | L8: بالغ | M8: خدمه ثلاثيه | S8: 43225
A9: محمد محمود فتحى امين خالد | B9: 2002-07-13 | C9: 30207131701037 | D9: A46139219 | E9: مطار برج العرب | F9: بنغازى | G9: الليبيه LN 209 | H9: 2026-08-21 | I9: 0.41666667 | J9: ابو سليم | L9: بالغ | M9: خدمه ثلاثيه | S9: 43225
A10: تقديم 21 اغسطس
A11: عبد الفتاح احمد عبد الفتاح احمد خاطر | B11: 1989-06-07 | C11: 28906072101531 | D11: A34781981 | E11: مطار القاهره | F11: بنغازى | G11: الليبيه LN 207 | H11: 2026-08-23 | I11: 0.41666667 | J11: ابو سليم | L11: بالغ | M11: خدمه ثلاثيه | S11: 43725
A12: تقديم 22 اغسطس
A13: با هر كرم اسحق عبد الملك | B13: 1985-04-28 | C13: 28504280102958 | D13: A33253812 | E13: مطار القاهره | F13: بنغازى | G13: الليبيه LN 207 | H13: 2026-08-23 | I13: 0.5 | J13: ابو سليم | L13: بالغ | M13: خدمه ثلاثيه | S13: 45000
A14: ايداع بنكي بتاريخ 23 اغسطس | T14: 169400
A15: تقديم 23 اغسطس
A16: جمال سعيد محمد الجوهرى الحبشى | B16: 1986-08-01 | C16: 28608011804997 | D16: A42346392 | E16: مطار برج العرب | F16: بنغازى | G16: البرنيق NB 401 | H16: 2026-08-24 | I16: 0.41666667 | J16: ابو سليم | L16: بالغ | M16: خدمه احاديه (م فقط) | S16: 25000
A17: سامى حسن عوض عيد | B17: 1986-05-21 | C17: 28/605211500071 | D17: A37997938 | E17: مطار القاهره | F17: بنغازى | G17: البرنيق NB 0451 | H17: 2026-08-25 | I17: 0.41666667 | J17: ابو سليم | L17: بالغ | M17: خدمه احاديه (م فقط) | S17: 25000
A18: محمد ناصر رضوان سيد عبد الجواد | B18: 2006-10-28 | C18: 30610282406397 | D18: A45554117 | E18: مطار برج العرب | F18: بنغازى | G18: البراق UZ 131 | H18: 2026-08-25 | I18: 0.41666667 | J18: ابو سليم | L18: بالغ | M18: خدمه ثلاثيه | S18: 44500
A19: محمد مصطفى معروف عبد الله على | B19: 2007-04-02 | C19: 30704022401957 | D19: A45809605 | E19: مطار برج العرب | F19: بنغازى | G19: البراق UZ 131 | H19: 2026-08-25 | I19: 0.41666667 | J19: ابو سليم | L19: بالغ | M19: خدمه ثلاثيه | S19: 44500
A20: تقديم 24 اغسطس
A21: محمد حامد محمد زكى مجاهد | B21: 2022-02-06 | C21: 22202061603151 | D21: A45660245 | E21: مطار برج العرب | F21: بنغازى | G21: البراق UZ 131 | H21: 2026-08-25 | I21: 0.41666667 | J21: ابو سليم | L21: طفل | M21: خدمه ثلاثيه | S21: 26000
A22: اسيا حامد محمد زكى مجاهد | B22: 2018-12-16 | C22: 31812161600884 | D22: A45660294 | E22: مطار برج العرب | F22: بنغازى | G22: البراق UZ 131 | H22: 2026-08-25 | I22: 0.41666667 | J22: ابو سليم | L22: طفل | M22: خدمه ثلاثيه | S22: 26000
A23: حامد محمد زكى مجاهد | B23: 1993-09-15 | C23: 29309151601898 | D23: A45660240 | E23: مطار برج العرب | F23: بنغازى | G23: البراق UZ 131 | H23: 2026-08-25 | I23: 0.41666667 | J23: ابو سليم | L23: بالغ | M23: خدمه ثلاثيه | S23: 44500
A24: محمود عبدالله احمد احمد البنا | B24: 1987-01-15 | C24: 28701151303815 | D24: A44913059 | E24: مطار القاهره | F24: بنغازى | G24: الليبيه LN 207 | H24: 2026-08-25 | I24: 0.41666667 | J24: ابو سليم | L24: بالغ | M24: خدمه ثلاثيه | S24: 45000
A25: تقديم 25 اغسطس
A26: السيد عبد الله محمد | B26: 1988-10-02 | C26: 28810021201356 | D26: A45923649 | E26: مطار برج العرب | F26: بنغازى | G26: البراق UZ 131 | H26: 2026-09-01 | I26: 0.41666667 | J26: ابو سليم | L26: بالغ | M26: خدمه ثلاثيه | S26: 44700
A27: ايمن موسى عطوه عامر | B27: 1986-08-03 | C27: 28608031601553 | D27: A42904790 | E27: مطار القاهره | F27: طرابلس | G27: اير كايرو SM 231 | H27: 2026-08-26 | I27: 0.41666667 | J27: ابو سليم | L27: بالغ | M27: خدمه احاديه (م فقط) | S27: 25200
I31: اجمالي المديونيه دولار | J31: =SUM(Q:Q)-SUM(R:R) -> 0
I32: اجمالي المديونيه مصري | J32: =SUM(S:S)-SUM(T:T) -> 395400
I33: الرئيسيه

Sheet مصطفي صادق
A1: الاسم | B1: تاريخ الميلاد | C1: الرقم القومي | D1: رقم الجواز | E1: المنفذ | F1: جهة السفر | G1: شركة الطيران | H1: تاريخ المغادرة | I1: ميعاد المغادرة | J1: الوكيل | K1: مورد الاستثمار | L1: ملاحظات | M1: نوع الخدمه | N1: ملاحظات | O1: ملاحظات | P1: ملاحظات | Q1: مدين دولار | R1: دائن دولار | S1: مدين مصري | T1: دائن مصري
A2: ما قبله | S2: 498121 | T2: 0
A4: تقديم 16 اغسطس
A5: ارزاق ابو المكارم مطاوع على | B5: 1999-11-21 | C5: 29911212103863 | D5: A44293154 | E5: مطار القاهره | F5: طرابلس | G5: اير كايرو SM 231 | H5: 2026-08-17 | I5: 0.41666667 | J5: مصطفي صادق | L5: انثى | M5: خدمه احاديه (م فقط) | S5: 22000
A6: عبد الله سعد عبد الله السعداوى | B6: 1989-11-20 | C6: 28911201502037 | D6: 28047198 | E6: مطار القاهره | F6: طرابلس | G6: اير كايرو SM 231 | H6: 2026-08-17 | I6: 0.41666667 | J6: مصطفي صادق | L6: بالغ | M6: خدمه احاديه (م فقط) | S6: 22000
A7: متولى محمد ابراهيم الفتيانى | B7: 1976-06-06 | C7: 27606061500691 | D7: A45459364 | E7: مطار برج العرب | F7: بنغازى | G7: اير ليبيا TLR 150 | H7: 2026-08-17 | I7: 0.29166667 | J7: مصطفي صادق | L7: بالغ | M7: خدمه ثلاثيه | S7: 43225
A8: محمد عصام محمد السيد صالح | B8: 2008-08-20 | C8: 30808201204218 | D8: A45921708 | E8: مطار برج العرب | F8: بنغازى | G8: اير ليبيا TLR 150 | H8: 2026-08-17 | I8: 0.29166667 | J8: مصطفي صادق | L8: بالغ | M8: خدمه ثلاثيه | S8: 43225
A9: حسنى هريدى حسن شلبى | B9: 2002-09-19 | C9: 20209192602956 | D9: A31946409 | E9: مطار برج العرب | F9: بنغازى | G9: اير ليبيا TLR 150 | H9: 2026-08-17 | I9: 0.29166667 | J9: مصطفي صادق | L9: بالغ | M9: خدمه ثلاثيه | S9: 43225
A10: يوسف مساعد سيد عاشور ابوزيد | B10: 2008-11-29 | C10: 30811292301491 | D10: A36317031 | E10: مطار برج العرب | F10: طرابلس | G10: الليبيه LN 211 | H10: 2026-08-17 | I10: 0.29166667 | J10: مصطفي صادق | L10: بالغ | M10: خدمه احاديه (م فقط) | S10: 22000
A11: احمد مبروك على محمد | B11: 2008-12-01 | C11: 30812012303695 | D11: A45406194 | E11: مطار برج العرب | F11: طرابلس | G11: الليبيه LN 211 | H11: 2026-08-17 | I11: 0.29166667 | J11: مصطفي صادق | L11: بالغ | M11: خدمه احاديه (م فقط) | S11: 22000
A12: امجد على عبد النظير محمود | B12: 2001-05-25 | C12: 30105252700359 | D12: A33945819 | E12: مطار برج العرب | F12: بنغازى | G12: اير ليبيا TLR 150 | H12: 2026-08-17 | I12: 0.29166667 | J12: مصطفي صادق | L12: بالغ | M12: خدمه ثلاثيه | S12: 43225
A13: احمد محمود ابراهيم محمد عبد اللطيف | B13: 2008-05-18 | C13: 30805182402659 | D13: A39903672 | E13: مطار برج العرب | F13: بنغازى | G13: اير ليبيا TLR 150 | H13: 2026-08-17 | I13: 0.29166667 | J13: مصطفي صادق | L13: بالغ | M13: خدمه ثلاثيه | S13: 43225
A14: محمد رجب الحسين السيد على | B14: 2009-07-01 | C14: 30907012307497 | D14: A44658240 | E14: مطار برج العرب | F14: بنغازى | G14: اير ليبيا TLR 150 | H14: 2026-08-17 | I14: 0.29166667 | J14: مصطفي صادق | L14: بالغ | M14: خدمه ثلاثيه | S14: 43225
A15: جمعه عبد التواب حسين السيد | B15: 1988-08-07 | C15: 28808072301075 | D15: A44949879 | E15: مطار برج العرب | F15: بنغازى | G15: اير ليبيا TLR 150 | H15: 2026-08-17 | I15: 0.29166667 | J15: مصطفي صادق | L15: بالغ | M15: خدمه ثلاثيه | S15: 43225
A16: عبد الله حلمى عبد الله حسنين | B16: 1994-08-10 | C16: 29408102703675 | D16: A43882776 | E16: مطار برج العرب | F16: بنغازى | G16: اير ليبيا TLR 150 | H16: 2026-08-17 | I16: 0.29166667 | J16: مصطفي صادق | L16: بالغ | M16: خدمه ثلاثيه | S16: 43225
... A44: حسام احمد عبد الحسيب احمد | B44: 1973-09-15 | C44: 27209151200438 | D44: A45613816 | E44: مطار القاهره | F44: طرابلس | G44: مصر للطيران MS 831 | H44: 2026-08-18 | I44: 0.27083333 | J44: مصطفي صادق | L44: بالغ | M44: خدمه ثنائيه (م+ت) | S44: 26000
A45: تقديم 17 اغسطس
A46: على رمضان ابراهيم على | B46: 1986-05-01 | C46: 28605012105155 | D46: A33956204 | E46: مطار برج العرب | F46: بنغازى | G46: اير ليبيا 7Q 148 | H46: 2026-08-18 | I46: 0.70833333 | J46: مصطفي صادق | L46: بالغ | M46: خدمه ثلاثيه | S46: 43225
A47: طارق ابراهيم ابراهيم الشهاوى | B47: 1980-11-05 | C47: 28011051500251 | D47: A45118840 | E47: مطار برج العرب | F47: طرابلس | G47: الليبيه LN 211 | H47: 2026-08-21 | I47: 0.41666667 | J47: مصطفي صادق | L47: بالغ | M47: خدمه ثنائيه (م+ت) | S47: 25000
A48: احمد محمود احمد عبد الله | B48: 1979-05-27 | C48: 27905272601571 | D48: A45739754 | E48: مطار برج العرب | F48: طرابلس | G48: الليبيه LN 211 | H48: 2026-08-21 | I48: 0.41666667 | J48: مصطفي صادق | L48: بالغ | M48: خدمه ثنائيه (م+ت) | S48: 25000
A49: محمود محمد محمد عبد الرحمن الصعيدى | B49: 1989-10-24 | C49: 28910241500731 | D49: A28049441 | E49: مطار برج العرب | F49: طرابلس | G49: الليبيه LN 211 | H49: 2026-08-21 | I49: 0.41666667 | J49: مصطفي صادق | L49: بالغ | M49: خدمه ثنائيه (م+ت) | S49: 25000
A50: محمود احمد محمود احمد عبد الله | B50: 2011-12-20 | C50: 31112202602518 | D50: A45739576 | E50: مطار برج العرب | F50: طرابلس | G50: الليبيه LN 211 | H50: 2026-08-21 | I50: 0.41666667 | J50: مصطفي صادق | L50: بالغ | M50: خدمه ثنائيه (م+ت) | S50: 25000
A51: مصطفى محمود السيد السيد الغفير | B51: 1980-01-06 | C51: 01061501993 | D51: A38654469 | E51: مطار القاهره | F51: طرابلس | G51: مصر للطيران MS 831 | H51: 2026-08-19 | I51: 0.125 | J51: مصطفي صادق | L51: بالغ | M51: خدمه ثنائيه (م+ت) | S51: 26000
A52: محمود عبد المحسن محمود محمود | B52: 1983-07-09 | C52: 28307090103451 | D52: A41248181 | E52: مطار القاهره | F52: طرابلس | G52: مصر للطيران MS 831 | H52: 2026-08-20 | I52: 0.125 | J52: مصطفي صادق | L52: بالغ | M52: خدمه ثنائيه (م+ت) | S52: 26000
A53: ابراهيم بليغ حمدى عبد الحميد الشافعى | B53: 2005-07-17 | C53: 20507171501174 | D53: A27619541 | E53: مطار برج العرب | F53: بنغازى | G53: اير ليبيا 7Q 148 | H53: 2026-08-18 | I53: 0.70833333 | J53: مصطفي صادق | L53: بالغ | M53: خدمه ثلاثيه | S53: 43225
A54: رفعت عبد الونيس السيد قطب رمضان | B54: 1990-05-31 | C54: 29005311600371 | D54: A45479424 | E54: مطار برج العرب | F54: بنغازى | G54: اير ليبيا 7Q 148 | H54: 2026-08-18 | I54: 0.70833333 | J54: مصطفي صادق | L54: بالغ | M54: خدمه ثلاثيه | S54: 43225
A55: محمود احمد محمد عبد اللاه | B55: 2007-10-28 | C55: 30710282600511 | D55: A33721975 | E55: مطار القاهره | F55: بنغازى | G55: الليبيه LN 207 | H55: 2026-08-18 | I55: 0.41666667 | J55: مصطفي صادق | L55: بالغ | M55: خدمه ثلاثيه | S55: 43725
A56: تامر صابر محمد عبد المجيد | B56: 1983-04-04 | C56: 28304041401332 | D56: A45948401 | E56: مطار القاهره | F56: بنغازى | G56: الليبيه LN 207 | H56: 2026-08-18 | I56: 0.41666667 | J56: مصطفي صادق | L56: بالغ | M56: خدمه ثلاثيه | S56: 43725
A57: احمد علاء مصطفى مصطفى | B57: 1996-10-01 | C57: 29610011816314 | D57: A39559025 | E57: مطار برج العرب | F57: بنغازى | G57: اير ليبيا 7Q 148 | H57: 2026-08-18 | I57: 0.70833333 | J57: مصطفي صادق | L57: بالغ | M57: خدمه ثلاثيه | S57: 43225
... A85: عبد الرحمن منير مصطفى ابراهيم | B85: 2001-10-24 | C85: 112301101 | D85: A36692739 | E85: مطار القاهره | F85: بنغازى | G85: الليبيه LN 207 | H85: 2026-08-18 | I85: 0.41666667 | J85: مصطفي صادق | L85: بالغ | M85: خدمه ثلاثيه | S85: 43725
A86: مدفوعه في حساب التحالف | T86: 3642300
A87: تقديم 21 اغسطس
A88: علاء محمد محمد ابراهيم الشاعر | B88: 1976-05-06 | C88: 27605061201158 | D88: A35825277 | E88: مطار القاهره | F88: طرابلس | G88: مصر للطيران MS 831 | H88: 2026-08-23 | I88: 0.125 | J88: مصطفي صادق | L88: بالغ | M88: خدمه ثنائيه (م+ت) | S88: 26000
A89: محمد حسن محمود عبد المجيد حبيشي | B89: 1986-12-13 | C89: 28612131203034 | D89: A40390047 | E89: مطار القاهره | F89: طرابلس | G89: مصر للطيران MS 831 | H89: 2026-08-23 | I89: 0.125 | J89: مصطفي صادق | L89: بالغ | M89: خدمه ثنائيه (م+ت) | S89: 26000
I97: اجمالي المديونيه دولار | J97: =SUM(Q:Q)-SUM(R:R) -> 0
I98: اجمالي المديونيه مصري | J98: =SUM(S:S)-SUM(T:T) -> 51996
I99: الرئيسيه

Sheet د يارا (2)
A1: الاسم | B1: تاريخ الميلاد | C1: الرقم القومي | D1: رقم الجواز | E1: المنفذ | F1: جهة السفر | G1: شركة الطيران | H1: تاريخ المغادرة | I1: ميعاد المغادرة | J1: الوكيل | K1: مورد الاستثمار | L1: ملاحظات | M1: نوع الخدمه | N1: ملاحظات | O1: ملاحظات | P1: ملاحظات | Q1: مدين دولار | R1: دائن دولار | S1: مدين مصري | T1: دائن مصري
A2: ما قبله | S2: 0 | T2: 0
A3: ايداع بنكي بتاريخ 10 اغسطس | T3: 22200
A4: تقديم 11 اغسطس
